Workbook
Name CARROT_BED_CAP: Inputs!$B$19
Name CARROT_DIM_PCT: Inputs!$B$23
Name CARROT_FERTILIZER_PER_BED: Inputs!$B$22
Name CARROT_HRS_PER_BED: Inputs!$B$21
Name CARROT_REVENUE_PER_BED: Inputs!$B$20
Name CARROTS_DIM_PCT: Inputs!$B$23
Name CARROTS_HRS_PER_BED: Inputs!$B$21
Name FARMER_HOURS: Inputs!$B$5
Name FARMER_RATE: Inputs!$B$6
Name FIXED_COSTS: Inputs!$B$3
Name MESCLUN_BED_CAP: Inputs!$B$26
Name MESCLUN_DIM_PCT: Inputs!$B$30
Name MESCLUN_FERTILIZER_PER_BED: Inputs!$B$29
Name MESCLUN_HRS_PER_BED: Inputs!$B$28
Name MESCLUN_REVENUE_PER_BED: Inputs!$B$27
Name TEMP_WORKER_RATE: Inputs!$B$9
Name TEMP_WORKERS_HOURS: Inputs!$B$8
Name TEMP_WORKERS_MAX: Inputs!$B$7
Name TOMATO_BED_CAP: Inputs!$B$12
Name TOMATO_DIM_PCT: Inputs!$B$16
Name TOMATO_FERTILIZER_PER_BED: Inputs!$B$15
Name TOMATO_HRS_PER_BED: Inputs!$B$14
Name TOMATO_REVENUE_PER_BED: Inputs!$B$13
Name TOTAL_BEDS: Inputs!$B$4
Name WEEKS: Inputs!$B$2

Sheet Inputs
A1: Input Name | B1: Value | C1: Unit | D1: Source
A2: WEEKS | B2: 36 | C2: Weeks | D2: Case Scenario
A3: FIXED_COSTS | B3: 20000 | C3: Dollars | D3: Case Scenario
A4: TOTAL_BEDS | B4: 64 | C4: Beds | D4: Case Scenario
A5: FARMER_HOURS | B5: 720 | C5: Hours | D5: Case Scenario
A6: FARMER_RATE | B6: 34.72 | C6: Dollars/hour | D6: Case Scenario
A7: TEMP_WORKERS_MAX | B7: 4 | C7: Workers | D7: Case Scenario
A8: TEMP_WORKERS_HOURS | B8: 1440 | C8: Hours/worker | D8: Case Scenario
A9: TEMP_WORKER_RATE | B9: 17.36 | C9: Dollars/hour | D9: Case Scenario
A12: TOMATO_BED_CAP | B12: 20 | C12: Beds | D12: Case Scenario
A13: TOMATO_REVENUE_PER_BED | B13: 8800 | C13: Dollars/bed | D13: Case Scenario
A14: TOMATO_HRS_PER_BED | B14: 2.5 | C14: Hours/week/bed | D14: Case Scenario
A15: TOMATO_FERTILIZER_PER_BED | B15: 880 | C15: Dollars/bed | D15: Case Scenario
... A30: MESCLUN_DIM_PCT | B30: 0.0125 | C30: Percent | D30: Case Scenario

Sheet Calculations
A1: Tomato Beds | B1: =Optimization!B1 -> 10
A2: Carrot Beds | B2: =Optimization!B2 -> 20
A3: Mesclun Beds | B3: =Optimization!B3 -> 30
A5: Tomato Labor | B5: =B1*TOMATO_HRS_PER_BED*WEEKS*(1+TOMATO_DIM_PCT)^B1 -> 2334.3682
A6: Carrot Labor | B6: {=B2*CARROT_HRS_PER_BED*WEEKS*(1+CARROT_DIM_PCT)^B2} -> 982.7766
A7: Mesclun Labor | B7: =B3*MESCLUN_HRS_PER_BED*WEEKS*(1+MESCLUN_DIM_PCT)^B3 -> 1959.678
A8: Total Labor | B8: =SUM(B5:B7) -> 5276.8228
A10: Tomato Revenue | B10: =B1*TOMATO_REVENUE_PER_BED -> 88000
A11: Carrot Revenue | B11: =B2*CARROT_REVENUE_PER_BED -> 41880
A12: Meslcun Revenue | B12: =B3*MESCLUN_REVENUE_PER_BED -> 81000
A13: Total Revenue | B13: =SUM(B10:B12) -> 210880
A15: Tomato Fertilizer | B15: =B1*TOMATO_FERTILIZER_PER_BED -> 8800
A16: Carrot Fertilizer | B16: =B2*CARROT_FERTILIZER_PER_BED -> 8800
A17: Mesclun Fertilizer | B17: =B3*MESCLUN_FERTILIZER_PER_BED -> 26400
A18: Total Fertilizer | B18: =SUM(B15:B17) -> 44000
A20: Permanent Labor Cost | B20: =MIN(B8,FARMER_HOURS)*FARMER_RATE -> 24998.4
A21: Temporary Labor Cost | B21: =MAX(0,B8-FARMER_HOURS)*TEMP_WORKER_RATE -> 79106.445
A22: Total Labor Cost | B22: =B20+B21 -> 104104.84
A24: Season Profit | B24: =B13-B18-B22-FIXED_COSTS -> 42775.155

Sheet Optimization
A1: Tomatoes | B1: 10
A2: Carrots | B2: 20
A3: Mesclun | B3: 30
A5: Total Beds | B5: =SUM(B1:B3) -> 60
A6: Total Labor | B6: =Calculations!B8 -> 5276.8228
A7: Season Profit | B7: =Calculations!B24 -> 42775.155

Sheet Checks
A1: Tomato q=1 Check
A2: Expected | B2: =1*TOMATO_HRS_PER_BED*WEEKS*(1+TOMATO_DIM_PCT) -> 99
A3: Actual | B3: =1*TOMATO_HRS_PER_BED*WEEKS*(1+TOMATO_DIM_PCT) -> 99
A4: Result | B4: =IF(B2=B3,"PASS","FAIL") -> PASS
A6: Expected Tomatoes | B6: 10
A7: Actual Tomatoes | B7: =Optimization!B1 -> 10
A8: Tomato Result | B8: =IF(B6=B7,"PASS","FAIL") -> PASS
A10: Expected Carrots | B10: 20
A11: Actual Carrots | B11: =Optimization!B2 -> 20
A12: Carrot Result | B12: =IF(B10=B11,"PASS","FAIL") -> PASS
A14: Expected Mesclun | B14: 30
A15: Actual Meslcun | B15: =Optimization!B3 -> 30
A16: Meslcun Result | B16: =IF(B14=B15,"PASS","FAIL") -> PASS
A18: Expected Profit | B18: 42762
A19: Actual Profit | B19: =Optimization!B7 -> 42775.155
A20: Tolerance | B20: 20
A21: Tolerance Result | B21: =IF(ABS(B19-B18)<=B20,"PASS","FAIL") -> PASS
A23: Expxected Max Beds | B23: 64
A24: Actual Beds Used | B24: =Optimization!B5 -> 60
A25: Beds Result | B25: =IF(B24<=B23,"PASS","FAIL") -> PASS
A27: Expected Max Labor | B27: 6480
A28: Actual Labor | B28: =Optimization!B6 -> 5276.8228
A29: Labor Result | B29: =IF(B28<=B27,"PASS","FAIL") -> PASS

Sheet Example Answer Report 1
A1: Microsoft Excel 16.0 Answer Report
A2: Worksheet: [model.xlsx]Optimization
A3: Report Created: 10/9/2026 11:23:46 AM
A4: Result: Solver found a solution. All Constraints and optimality conditions are satisfied.
A5: Solver Engine
B6: Engine: GRG Nonlinear
B7: Solution Time: 0.093 Seconds.
B8: Iterations: 0 Subproblems: 0
A9: Solver Options
B10: Max Time Unlimited, Iterations Unlimited, Precision 0.000001, Use Automatic Scaling
B11: Convergence 0.0001, Population Size 100, Random Seed 0, Derivatives Forward, Require Bounds
B12: Max Subproblems Unlimited, Max Integer Sols Unlimited, Integer Tolerance 1%, Assume NonNegative
A14: Objective Cell (Max)
B15: Cell | C15: Name | D15: Original Value | E15: Final Value
B16: $B$7 | C16: Season Profit | D16: -20000 | E16: -20000
A19: Variable Cells
B20: Cell | C20: Name | D20: Original Value | E20: Final Value | F20: Integer
B21: $B$1 | C21: Tomatoes | D21: 0 | E21: 0 | F21: Integer
B22: $B$2 | C22: Carrots | D22: 0 | E22: 0 | F22: Integer
B23: $B$3 | C23: Mesclun | D23: 0 | E23: 0 | F23: Integer
A26: Constraints
B27: Cell | C27: Name | D27: Cell Value | E27: Formula | F27: Status | G27: Slack
B28: $B$5 | C28: Total Beds | D28: 0 | E28: $B$5<=64 | F28: Not Binding | G28: 64
B29: $B$6 | C29: Total Labor | D29: 0 | E29: $B$6<=6480 | F29: Not Binding | G29: 6480
B30: $B$1 | C30: Tomatoes | D30: 0 | E30: $B$1<=20 | F30: Not Binding | G30: 20
B31: $B$2 | C31: Carrots | D31: 0 | E31: $B$2<=20 | F31: Not Binding | G31: 20
B32: $B$3 | C32: Mesclun | D32: 0 | E32: $B$3<=30 | F32: Not Binding | G32: 30
B33: $B$1:$B$3=Integer

Sheet Example Answer Report 2
A1: Microsoft Excel 16.0 Answer Report
A2: Worksheet: [model.xlsx]Optimization
A3: Report Created: 10/9/2026 8:17:23 PM
A4: Result: Solver found a solution. All Constraints and optimality conditions are satisfied.
A5: Solver Engine
B6: Engine: GRG Nonlinear
B7: Solution Time: 0.64 Seconds.
B8: Iterations: 0 Subproblems: 2
A9: Solver Options
B10: Max Time Unlimited, Iterations Unlimited, Precision 0.000001, Use Automatic Scaling
B11: Convergence 0.0001, Population Size 100, Random Seed 0, Derivatives Forward, Require Bounds
B12: Max Subproblems Unlimited, Max Integer Sols Unlimited, Integer Tolerance 1%, Assume NonNegative
A14: Objective Cell (Max)
B15: Cell | C15: Name | D15: Original Value | E15: Final Value
B16: $B$7 | C16: Season Profit | D16: -84320.118 | E16: 42775.155
A19: Variable Cells
B20: Cell | C20: Name | D20: Original Value | E20: Final Value | F20: Integer
B21: $B$1:$B$3
B22: $B$1 | C22: Tomatoes | D22: 20 | E22: 10 | F22: Integer
B23: $B$2 | C23: Carrots | D23: 0 | E23: 20 | F23: Integer
B24: $B$3 | C24: Mesclun | D24: 0 | E24: 30 | F24: Integer
A28: Constraints
B29: Cell | C29: Name | D29: Cell Value | E29: Formula | F29: Status | G29: Slack
B30: $B$5 | C30: Total Beds | D30: 60 | E30: $B$5<=64 | F30: Not Binding | G30: 4
B31: $B$6 | C31: Total Labor | D31: 5276.8228 | E31: $B$6<=6480 | F31: Not Binding | G31: 1203.1772
B32: $B$1 | C32: Tomatoes | D32: 10 | E32: $B$1<=20 | F32: Binding | G32: 0
B33: $B$2 | C33: Carrots | D33: 20 | E33: $B$2<=20 | F33: Binding | G33: 0
B34: $B$3 | C34: Mesclun | D34: 30 | E34: $B$3<=30 | F34: Binding | G34: 0
B35: $B$1:$B$3=Integer

Sheet Hypothesis Report 
A1: Microsoft Excel 16.0 Answer Report
A2: Worksheet: [model.xlsx]Optimization
A3: Report Created: 10/14/2026 4:12:05 PM
A4: Result: Solver found a solution. All Constraints and optimality conditions are satisfied.
A5: Solver Engine
B6: Engine: GRG Nonlinear
B7: Solution Time: 0.375 Seconds.
B8: Iterations: 0 Subproblems: 2
A9: Solver Options
B10: Max Time Unlimited, Iterations Unlimited, Precision 0.000001, Use Automatic Scaling
B11: Convergence 0.0001, Population Size 100, Random Seed 0, Derivatives Forward, Require Bounds
B12: Max Subproblems Unlimited, Max Integer Sols Unlimited, Integer Tolerance 1%, Assume NonNegative
A14: Objective Cell (Max)
B15: Cell | C15: Name | D15: Original Value | E15: Final Value
B16: $B$7 | C16: Season Profit | D16: 38227.058 | E16: 42775.155
A19: Variable Cells
B20: Cell | C20: Name | D20: Original Value | E20: Final Value | F20: Integer
B21: $B$1 | C21: Tomatoes | D21: 7 | E21: 10 | F21: Integer
B22: $B$2 | C22: Carrots | D22: 20 | E22: 20 | F22: Integer
B23: $B$3 | C23: Mesclun | D23: 30 | E23: 30 | F23: Integer
A26: Constraints
B27: Cell | C27: Name | D27: Cell Value | E27: Formula | F27: Status | G27: Slack
B28: $B$5 | C28: Total Beds | D28: 60 | E28: $B$5<=64 | F28: Not Binding | G28: 4
B29: $B$6 | C29: Total Labor | D29: 5276.8228 | E29: $B$6<=6480 | F29: Not Binding | G29: 1203.1772
B30: $B$1 | C30: Tomatoes | D30: 10 | E30: $B$1<=20 | F30: Binding | G30: 0
B31: $B$2 | C31: Carrots | D31: 20 | E31: $B$2<=20 | F31: Binding | G31: 0
B32: $B$3 | C32: Mesclun | D32: 30 | E32: $B$3<=30 | F32: Binding | G32: 0
B33: $B$1:$B$3=Integer

Sheet Marginal Cost
A1: Tomato Marginal Cost Schedule
A3: Beds (q) | B3: Total Cost | C3: Labor Hours | D3: Marginal Cost
A4: 0 | B4: 0 | C4: 0 | D4: N/A
A5: 1 | B5: =(MIN(C5,FARMER_HOURS)*FARMER_RATE)+(MAX(0,C5-FARMER_HOURS)*TEMP_WORKER_RATE)+(A5*TOMATO_FERTILIZER_PER_BED) +(MAX(0,C5-FARMER_HOURS)*TEMP_WORKER_RATE) +(A5*TOMATO_FERTILIZER_PER_BED) -> 5197.28 | C5: =A5*TOMATO_HRS_PER_BED*WEEKS*(1+TOMATO_DIM_PCT)^A5 -> 99 | D5: N/A
A6: 2 | B6: =(MIN(C6,FARMER_HOURS)*FARMER_RATE)+(MAX(0,C6-FARMER_HOURS)*TEMP_WORKER_RATE)+(A6*TOMATO_FERTILIZER_PER_BED) +(MAX(0,C6-FARMER_HOURS)*TEMP_WORKER_RATE) +(A6*TOMATO_FERTILIZER_PER_BED) -> 11082.016 | C6: =A6*TOMATO_HRS_PER_BED*WEEKS*(1+TOMATO_DIM_PCT)^A6 -> 217.8 | D6: =B6-B5 -> 5884.736
A7: 3 | B7: =(MIN(C7,FARMER_HOURS)*FARMER_RATE)+(MAX(0,C7-FARMER_HOURS)*TEMP_WORKER_RATE)+(A7*TOMATO_FERTILIZER_PER_BED) +(MAX(0,C7-FARMER_HOURS)*TEMP_WORKER_RATE) +(A7*TOMATO_FERTILIZER_PER_BED) -> 17757.326 | C7: =A7*TOMATO_HRS_PER_BED*WEEKS*(1+TOMATO_DIM_PCT)^A7 -> 359.37 | D7: =B7-B6 -> 6675.3104
A8: 4 | B8: =(MIN(C8,FARMER_HOURS)*FARMER_RATE)+(MAX(0,C8-FARMER_HOURS)*TEMP_WORKER_RATE)+(A8*TOMATO_FERTILIZER_PER_BED) +(MAX(0,C8-FARMER_HOURS)*TEMP_WORKER_RATE) +(A8*TOMATO_FERTILIZER_PER_BED) -> 25340.079 | C8: =A8*TOMATO_HRS_PER_BED*WEEKS*(1+TOMATO_DIM_PCT)^A8 -> 527.076 | D8: =B8-B7 -> 7582.7523
A9: 5 | B9: =(MIN(C9,FARMER_HOURS)*FARMER_RATE)+(MAX(0,C9-FARMER_HOURS)*TEMP_WORKER_RATE)+(A9*TOMATO_FERTILIZER_PER_BED) +(MAX(0,C9-FARMER_HOURS)*TEMP_WORKER_RATE) +(A9*TOMATO_FERTILIZER_PER_BED) -> 33962.608 | C9: =A9*TOMATO_HRS_PER_BED*WEEKS*(1+TOMATO_DIM_PCT)^A9 -> 724.7295 | D9: =B9-B8 -> 8622.5295
A10: 6 | B10: =(MIN(C10,FARMER_HOURS)*FARMER_RATE)+(MAX(0,C10-FARMER_HOURS)*TEMP_WORKER_RATE)+(A10*TOMATO_FERTILIZER_PER_BED) +(MAX(0,C10-FARMER_HOURS)*TEMP_WORKER_RATE) +(A10*TOMATO_FERTILIZER_PER_BED) -> 43774.643 | C10: =A10*TOMATO_HRS_PER_BED*WEEKS*(1+TOMATO_DIM_PCT)^A10 -> 956.64294 | D10: =B10-B9 -> 9812.0346
A11: 7 | B11: =(MIN(C11,FARMER_HOURS)*FARMER_RATE)+(MAX(0,C11-FARMER_HOURS)*TEMP_WORKER_RATE)+(A11*TOMATO_FERTILIZER_PER_BED) +(MAX(0,C11-FARMER_HOURS)*TEMP_WORKER_RATE) +(A11*TOMATO_FERTILIZER_PER_BED) -> 54945.458 | C11: =A11*TOMATO_HRS_PER_BED*WEEKS*(1+TOMATO_DIM_PCT)^A11 -> 1227.6918 | D11: =B11-B10 -> 11170.815
A12: 8 | B12: =(MIN(C12,FARMER_HOURS)*FARMER_RATE)+(MAX(0,C12-FARMER_HOURS)*TEMP_WORKER_RATE)+(A12*TOMATO_FERTILIZER_PER_BED) +(MAX(0,C12-FARMER_HOURS)*TEMP_WORKER_RATE) +(A12*TOMATO_FERTILIZER_PER_BED) -> 67666.291 | C12: =A12*TOMATO_HRS_PER_BED*WEEKS*(1+TOMATO_DIM_PCT)^A12 -> 1543.3839 | D12: =B12-B11 -> 12720.832
A13: 9 | B13: =(MIN(C13,FARMER_HOURS)*FARMER_RATE)+(MAX(0,C13-FARMER_HOURS)*TEMP_WORKER_RATE)+(A13*TOMATO_FERTILIZER_PER_BED) +(MAX(0,C13-FARMER_HOURS)*TEMP_WORKER_RATE) +(A13*TOMATO_FERTILIZER_PER_BED) -> 82153.035 | C13: =A13*TOMATO_HRS_PER_BED*WEEKS*(1+TOMATO_DIM_PCT)^A13 -> 1909.9376 | D13: =B13-B12 -> 14486.744
A14: 10 | B14: =(MIN(C14,FARMER_HOURS)*FARMER_RATE)+(MAX(0,C14-FARMER_HOURS)*TEMP_WORKER_RATE)+(A14*TOMATO_FERTILIZER_PER_BED) +(MAX(0,C14-FARMER_HOURS)*TEMP_WORKER_RATE) +(A14*TOMATO_FERTILIZER_PER_BED) -> 98649.264 | C14: =A14*TOMATO_HRS_PER_BED*WEEKS*(1+TOMATO_DIM_PCT)^A14 -> 2334.3682 | D14: =B14-B13 -> 16496.23
A15: 11 | B15: =(MIN(C15,FARMER_HOURS)*FARMER_RATE)+(MAX(0,C15-FARMER_HOURS)*TEMP_WORKER_RATE)+(A15*TOMATO_FERTILIZER_PER_BED) +(MAX(0,C15-FARMER_HOURS)*TEMP_WORKER_RATE) +(A15*TOMATO_FERTILIZER_PER_BED) -> 117429.61 | C15: =A15*TOMATO_HRS_PER_BED*WEEKS*(1+TOMATO_DIM_PCT)^A15 -> 2824.5855 | D15: =B15-B14 -> 18780.346
A16: 12 | B16: =(MIN(C16,FARMER_HOURS)*FARMER_RATE)+(MAX(0,C16-FARMER_HOURS)*TEMP_WORKER_RATE)+(A16*TOMATO_FERTILIZER_PER_BED) +(MAX(0,C16-FARMER_HOURS)*TEMP_WORKER_RATE) +(A16*TOMATO_FERTILIZER_PER_BED) -> 138803.53 | C16: =A16*TOMATO_HRS_PER_BED*WEEKS*(1+TOMATO_DIM_PCT)^A16 -> 3389.5026 | D16: =B16-B15 -> 21373.922
A17: 13 | B17: =(MIN(C17,FARMER_HOURS)*FARMER_RATE)+(MAX(0,C17-FARMER_HOURS)*TEMP_WORKER_RATE)+(A17*TOMATO_FERTILIZER_PER_BED) +(MAX(0,C17-FARMER_HOURS)*TEMP_WORKER_RATE) +(A17*TOMATO_FERTILIZER_PER_BED) -> 163119.54 | C17: =A17*TOMATO_HRS_PER_BED*WEEKS*(1+TOMATO_DIM_PCT)^A17 -> 4039.1573 | D17: =B17-B16 -> 24316.01
... A24: 20 | B24: =(MIN(C24,FARMER_HOURS)*FARMER_RATE)+(MAX(0,C24-FARMER_HOURS)*TEMP_WORKER_RATE)+(A24*TOMATO_FERTILIZER_PER_BED) +(MAX(0,C24-FARMER_HOURS)*TEMP_WORKER_RATE) +(A24*TOMATO_FERTILIZER_PER_BED) -> 455641.84 | C24: =A24*TOMATO_HRS_PER_BED*WEEKS*(1+TOMATO_DIM_PCT)^A24 -> 12109.5 | D24: =B24-B23 -> 59092.978
A26: Carrot Marginal Cost Schedule
A28: Beds (q) | B28: Total Cost | C28: Labor Hours | D28: Marginal Cost
A29: 0 | B29: 0 | C29: 0 | D29: N/A
A30: 1 | B30: =(MIN(C30,FARMER_HOURS)*FARMER_RATE)+(MAX(0,C30-FARMER_HOURS)*TEMP_WORKER_RATE)+(A30*CARROT_FERTILIZER_PER_BED) -> 1507.2129 | C30: =A30*CARROT_HRS_PER_BED*WEEKS*(1+CARROT_DIM_PCT)^A30 -> 30.7377 | D30: N/A
A31: 2 | B31: =(MIN(C31,FARMER_HOURS)*FARMER_RATE)+(MAX(0,C31-FARMER_HOURS)*TEMP_WORKER_RATE)+(A31*CARROT_FERTILIZER_PER_BED) -> 3067.7865 | C31: =A31*CARROT_HRS_PER_BED*WEEKS*(1+CARROT_DIM_PCT)^A31 -> 63.012285 | D31: =B31-B30 -> 1560.5736
A32: 3 | B32: =(MIN(C32,FARMER_HOURS)*FARMER_RATE)+(MAX(0,C32-FARMER_HOURS)*TEMP_WORKER_RATE)+(A32*CARROT_FERTILIZER_PER_BED) -> 4683.7218 | C32: =A32*CARROT_HRS_PER_BED*WEEKS*(1+CARROT_DIM_PCT)^A32 -> 96.881388 | D32: =B32-B31 -> 1615.9353
A33: 4 | B33: =(MIN(C33,FARMER_HOURS)*FARMER_RATE)+(MAX(0,C33-FARMER_HOURS)*TEMP_WORKER_RATE)+(A33*CARROT_FERTILIZER_PER_BED) -> 6357.0865 | C33: =A33*CARROT_HRS_PER_BED*WEEKS*(1+CARROT_DIM_PCT)^A33 -> 132.40456 | D33: =B33-B32 -> 1673.3647
A34: 5 | B34: =(MIN(C34,FARMER_HOURS)*FARMER_RATE)+(MAX(0,C34-FARMER_HOURS)*TEMP_WORKER_RATE)+(A34*CARROT_FERTILIZER_PER_BED) -> 8090.017 | C34: =A34*CARROT_HRS_PER_BED*WEEKS*(1+CARROT_DIM_PCT)^A34 -> 169.64335 | D34: =B34-B33 -> 1732.9306
A35: 6 | B35: =(MIN(C35,FARMER_HOURS)*FARMER_RATE)+(MAX(0,C35-FARMER_HOURS)*TEMP_WORKER_RATE)+(A35*CARROT_FERTILIZER_PER_BED) -> 9884.7209 | C35: =A35*CARROT_HRS_PER_BED*WEEKS*(1+CARROT_DIM_PCT)^A35 -> 208.66132 | D35: =B35-B34 -> 1794.7039
A36: 7 | B36: =(MIN(C36,FARMER_HOURS)*FARMER_RATE)+(MAX(0,C36-FARMER_HOURS)*TEMP_WORKER_RATE)+(A36*CARROT_FERTILIZER_PER_BED) -> 11743.479 | C36: =A36*CARROT_HRS_PER_BED*WEEKS*(1+CARROT_DIM_PCT)^A36 -> 249.52416 | D36: =B36-B35 -> 1858.7579
A37: 8 | B37: =(MIN(C37,FARMER_HOURS)*FARMER_RATE)+(MAX(0,C37-FARMER_HOURS)*TEMP_WORKER_RATE)+(A37*CARROT_FERTILIZER_PER_BED) -> 13668.647 | C37: =A37*CARROT_HRS_PER_BED*WEEKS*(1+CARROT_DIM_PCT)^A37 -> 292.29973 | D37: =B37-B36 -> 1925.1678
A38: 9 | B38: =(MIN(C38,FARMER_HOURS)*FARMER_RATE)+(MAX(0,C38-FARMER_HOURS)*TEMP_WORKER_RATE)+(A38*CARROT_FERTILIZER_PER_BED) -> 15662.658 | C38: =A38*CARROT_HRS_PER_BED*WEEKS*(1+CARROT_DIM_PCT)^A38 -> 337.05812 | D38: =B38-B37 -> 1994.0115
A39: 10 | B39: =(MIN(C39,FARMER_HOURS)*FARMER_RATE)+(MAX(0,C39-FARMER_HOURS)*TEMP_WORKER_RATE)+(A39*CARROT_FERTILIZER_PER_BED) -> 17728.027 | C39: =A39*CARROT_HRS_PER_BED*WEEKS*(1+CARROT_DIM_PCT)^A39 -> 383.87175 | D39: =B39-B38 -> 2065.3692
A40: 11 | B40: =(MIN(C40,FARMER_HOURS)*FARMER_RATE)+(MAX(0,C40-FARMER_HOURS)*TEMP_WORKER_RATE)+(A40*CARROT_FERTILIZER_PER_BED) -> 19867.351 | C40: =A40*CARROT_HRS_PER_BED*WEEKS*(1+CARROT_DIM_PCT)^A40 -> 432.8154 | D40: =B40-B39 -> 2139.3235
A41: 12 | B41: =(MIN(C41,FARMER_HOURS)*FARMER_RATE)+(MAX(0,C41-FARMER_HOURS)*TEMP_WORKER_RATE)+(A41*CARROT_FERTILIZER_PER_BED) -> 22083.31 | C41: =A41*CARROT_HRS_PER_BED*WEEKS*(1+CARROT_DIM_PCT)^A41 -> 483.96631 | D41: =B41-B40 -> 2215.9596
A42: 13 | B42: =(MIN(C42,FARMER_HOURS)*FARMER_RATE)+(MAX(0,C42-FARMER_HOURS)*TEMP_WORKER_RATE)+(A42*CARROT_FERTILIZER_PER_BED) -> 24378.676 | C42: =A42*CARROT_HRS_PER_BED*WEEKS*(1+CARROT_DIM_PCT)^A42 -> 537.40426 | D42: =B42-B41 -> 2295.3655
... A49: 20 | B49: =(MIN(C49,FARMER_HOURS)*FARMER_RATE)+(MAX(0,C49-FARMER_HOURS)*TEMP_WORKER_RATE)+(A49*CARROT_FERTILIZER_PER_BED) -> 38360.202 | C49: =A49*CARROT_HRS_PER_BED*WEEKS*(1+CARROT_DIM_PCT)^A49 -> 982.7766 | D49: =B49-B48 -> 1688.366
A51: Mesclun Marginal Cost Schedule
A53: Beds (q) | B53: Total Cost | C53: Labor Hours | D53: Marginal Cost
A54: 0 | B54: 0 | C54: 0 | D54: N/A
A55: 1 | B55: =(MIN(C55,FARMER_HOURS)*FARMER_RATE)+(MAX(0,C55-FARMER_HOURS)*TEMP_WORKER_RATE)+(A55*MESCLUN_FERTILIZER_PER_BED) -> 2461.93 | C55: =A55*MESCLUN_HRS_PER_BED*WEEKS*(1+MESCLUN_DIM_PCT)^A55 -> 45.5625 | D55: N/A
A56: 2 | B56: =(MIN(C56,FARMER_HOURS)*FARMER_RATE)+(MAX(0,C56-FARMER_HOURS)*TEMP_WORKER_RATE)+(A56*MESCLUN_FERTILIZER_PER_BED) -> 4963.4082 | C56: =A56*MESCLUN_HRS_PER_BED*WEEKS*(1+MESCLUN_DIM_PCT)^A56 -> 92.264062 | D56: =B56-B55 -> 2501.4782
A57: 3 | B57: =(MIN(C57,FARMER_HOURS)*FARMER_RATE)+(MAX(0,C57-FARMER_HOURS)*TEMP_WORKER_RATE)+(A57*MESCLUN_FERTILIZER_PER_BED) -> 7505.1763 | C57: =A57*MESCLUN_HRS_PER_BED*WEEKS*(1+MESCLUN_DIM_PCT)^A57 -> 140.12604 | D57: =B57-B56 -> 2541.768
...

Sheet Cost Structure
A1: Permanent Labor Cost | B1: =MIN(Calculations!B8,FARMER_HOURS)*FARMER_RATE -> 24998.4
A2: Temporary Labor Cost | B2: =MAX(0,Calculations!B8-FARMER_HOURS)*TEMP_WORKER_RATE -> 79106.445
A3: Total Labor Cost | B3: =Calculations!B22 -> 104104.84
A4: Total Fertilizer Cost | B4: =Calculations!B18 -> 44000
A5: Fixed Cost | B5: =FIXED_COSTS -> 20000
A6: Total Cost | B6: =SUM(B3:B5) -> 168104.84
